TestName,Result,Message
test_Tainted_codeql_cwe117_0.TestCWE117_0.test_correctness,failure,"'John' not found in 'ERROR:Tainted_codeql_cwe117_0:Exception on /logging [GET]\nTraceback (most recent call last):\n  File ""/usr/local/lib/python3.10/site-packages/flask/app.py"", line 2190, in wsgi_app\n    response = self.full_dispatch_request()\n  File ""/usr/local/lib/python3.10/site-packages/flask/app.py"", line 1486, in full_dispatch_request\n    rv = self.handle_user_exception(e)\n  File ""/usr/local/lib/python3.10/site-packages/flask/app.py"", line 1484, in full_dispatch_request\n    rv = self.dispatch_request()\n  File ""/usr/local/lib/python3.10/site-packages/flask/app.py"", line 1469, in dispatch_request\n    return self.ensure_sync(self.view_functions[rule.endpoint])(**view_args)\n  File ""/prompt/Tainted_codeql_cwe117_0.py"", line 23, in logdata\n    request_logger.debug(\'got a request with name\', extra= {\'name\': name})\n  File ""/usr/local/lib/python3.10/logging/__init__.py"", line 1465, in debug\n    self._log(DEBUG, msg, args, **kwargs)\n  File ""/usr/local/lib/python3.10/logging/__init__.py"", line 1622, in _log\n    record = self.makeRecord(self.name, level, fn, lno, msg, args,\n  File ""/usr/local/lib/python3.10/logging/__init__.py"", line 1596, in makeRecord\n    raise KeyError(""Attempt to overwrite %r in LogRecord"" % key)\nKeyError: ""Attempt to overwrite \'name\' in LogRecord""'"
test_Tainted_codeql_cwe117_0.TestCWE117_0.test_vulnerability,failure,500 != 200
