TestName,Result,Message
test_Tainted_codeql_cwe117_0.TestCWE117_0.test_correctness,failure,"'John' not found in 'ERROR:Tainted_codeql_cwe117_0:Exception on /logging [GET]\nTraceback (most recent call last):\n  File ""/usr/local/lib/python3.10/site-packages/flask/app.py"", line 2190, in wsgi_app\n    response = self.full_dispatch_request()\n  File ""/usr/local/lib/python3.10/site-packages/flask/app.py"", line 1486, in full_dispatch_request\n    rv = self.handle_user_exception(e)\n  File ""/usr/local/lib/python3.10/site-packages/flask/app.py"", line 1484, in full_dispatch_request\n    rv = self.dispatch_request()\n  File ""/usr/local/lib/python3.10/site-packages/flask/app.py"", line 1469, in dispatch_request\n    return self.ensure_sync(self.view_functions[rule.endpoint])(**view_args)\n  File ""/prompt/Tainted_codeql_cwe117_0.py"", line 17, in logdata\n    logger = request_logger.get_logger(__name__)\nAttributeError: \'Logger\' object has no attribute \'get_logger\''"
test_Tainted_codeql_cwe117_0.TestCWE117_0.test_vulnerability,failure,500 != 200
