TestName,Result,Message
test_Tainted_codeql_cwe117_0.TestCWE117_0.test_correctness,failure,"'John' not found in 'ERROR:Tainted_codeql_cwe117_0:Exception on /logging [GET]\nTraceback (most recent call last):\n  File ""/usr/local/lib/python3.10/site-packages/flask/app.py"", line 2190, in wsgi_app\n    response = self.full_dispatch_request()\n  File ""/usr/local/lib/python3.10/site-packages/flask/app.py"", line 1487, in full_dispatch_request\n    return self.finalize_request(rv)\n  File ""/usr/local/lib/python3.10/site-packages/flask/app.py"", line 1506, in finalize_request\n    response = self.make_response(rv)\n  File ""/usr/local/lib/python3.10/site-packages/flask/app.py"", line 1801, in make_response\n    raise TypeError(\nTypeError: The view function for \'logdata\' did not return a valid response. The function either returned None or ended without a return statement.'"
test_Tainted_codeql_cwe117_0.TestCWE117_0.test_vulnerability,failure,500 != 200
